<?xml version="1.0" ?>
<robot name="">
    <link name="base_link">
      <inertial>
        <origin rpy="0 0 0" xyz="0 0 0"/>
        <mass value="0.1"/>
        <inertia ixx="0.1" ixy="0" ixz="0" iyy="0.1" iyz="0" izz="0.1"/>
      </inertial>
    </link>

    <joint name="base_to_torso" type="continuous">
      <parent link="base_link"/>
      <child link="torso"/>
      <origin rpy="0 0 0" xyz="0 0 1.0"/>
    </joint>

	<link name="torso">
		<inertial>
			<origin rpy="0.00000 -0.00000 0.00000" xyz="0.00000 0.00000 1.25000"/>
			<mass value="3.66519"/>
			<inertia ixx="0.07941" ixy="0" ixz="0" iyy="0.07941" iyz="0" izz="0.00611"/>
		</inertial>
		<collision>
			<origin rpy="3.14159 -0.00000 3.14159" xyz="0.00000 0.00000 1.25000"/>
			<geometry>
				<cylinder length="0.40000" radius="0.05000"/>
			</geometry>
		</collision>
		<visual>
			<origin rpy="3.14159 -0.00000 3.14159" xyz="0.00000 0.00000 1.25000"/>
			<geometry>
				<cylinder length="0.40000" radius="0.05000"/>
			</geometry>
			<material name="red">
				<color rgba="1.0 0. 0. 0.9"/>
			</material>
		</visual>
	</link>

	<link name="thigh">
		<inertial>
			<origin rpy="0.00000 -0.00000 0.00000" xyz="0.00000 0.00000 0.82500"/>
			<mass value="4.05789"/>
			<inertia ixx="0.10567" ixy="0" ixz="0" iyy="0.10567" iyz="0" izz="0.00676"/>
		</inertial>
		<collision>
			<origin rpy="3.14159 -0.00000 3.14159" xyz="0.00000 0.00000 0.82500"/>
			<geometry>
				<cylinder length="0.45000" radius="0.05000"/>
			</geometry>
		</collision>
		<visual>
			<origin rpy="3.14159 -0.00000 3.14159" xyz="0.00000 0.00000 0.82500"/>
			<geometry>
				<cylinder length="0.45000" radius="0.05000"/>
			</geometry>
			<material name="green">
				<color rgba="0.0 1. 0. 0.9"/>
			</material>
		</visual>
	</link>
	<link name="leg">
		<inertial>
			<origin rpy="0.00000 -0.00000 0.00000" xyz="0.00000 0.00000 0.35000"/>
			<mass value="2.78136"/>
			<inertia ixx="0.07945" ixy="0" ixz="0" iyy="0.07945" iyz="0" izz="0.00297"/>
		</inertial>
		<collision>
			<origin rpy="3.14159 -0.00000 3.14159" xyz="0.00000 0.00000 0.35000"/>
			<geometry>
				<cylinder length="0.50000" radius="0.04000"/>
			</geometry>
		</collision>
		<visual>
			<origin rpy="3.14159 -0.00000 3.14159" xyz="0.00000 0.00000 0.35000"/>
			<geometry>
				<cylinder length="0.50000" radius="0.04000"/>
			</geometry>
			<material name="red">
				<color rgba="1.0 0. 0. 0.9"/>
			</material>
		</visual>
	</link>
	<link name="foot">
		<inertial>
			<origin rpy="0.00000 -0.00000 0.00000" xyz="0.06500 0.00000 0.10000"/>
			<mass value="5.31557"/>
			<inertia ixx="0.01276" ixy="0" ixz="0" iyy="0.12159" iyz="0" izz="0.12159"/>
		</inertial>
		<collision>
			<origin rpy="0.00000 1.57080 -0.00000" xyz="0.06500 0.00000 0.10000"/>
			<geometry>
				<cylinder length="0.39000" radius="0.06000"/>
			</geometry>
		</collision>
		<visual>
			<origin rpy="0.00000 1.57080 -0.00000" xyz="0.06500 0.00000 0.10000"/>
			<geometry>
				<cylinder length="0.39000" radius="0.06000"/>
			</geometry>
			<material name="green">
				<color rgba="0.0 1. 0. 0.8"/>
			</material>
		</visual>
	</link>

	<joint name="thigh_joint" type="revolute">
		<parent link="torso"/>
		<!-- <child link="link0_6"/> -->
		<child link="thigh"/>
		<limit effort="1000.0" lower="-0.50000" upper="0.50000" velocity="0.5"/>
		<dynamics damping="1.0" friction="0.0001"/>
		<origin rpy="0.00000 -0.00000 0.00000" xyz="0.00000 0.00000 0.00000"/>
		<axis xyz="0.00000 1.00000 0.00000"/>
	</joint>
	<joint name="leg_joint" type="revolute">
		<parent link="thigh"/>
		<child link="leg"/>
		<limit effort="1000.0" lower="-0.50000" upper="0.50000" velocity="0.5"/>
		<dynamics damping="1.0" friction="0.0001"/>
		<origin rpy="0.00000 -0.00000 0.00000" xyz="0.00000 0.00000 0.00000"/>
		<axis xyz="0.00000 1.00000 0.00000"/>
	</joint>
	<joint name="foot_joint" type="revolute">
		<parent link="leg"/>
		<child link="foot"/>
		<limit effort="1000.0" lower="-0.50000" upper="0.50000" velocity="0.5"/>
		<dynamics damping="1.0" friction="0.0001"/>
		<origin rpy="0.00000 -0.00000 0.00000" xyz="0.00000 0.00000 0.00000"/>
		<axis xyz="0.00000 1.00000 0.00000"/>
	</joint>
</robot>